<sdf version='1.7'>
  <world name='perception_world'>
    <model name='ground_plane'>
      <static>1</static>
      <link name='link'>
        <collision name='collision'>
          <geometry>
            <plane>
              <normal>0 0 1</normal>
              <size>100 100</size>
            </plane>
          </geometry>
          <surface>
            <friction>
              <ode>
                <mu>100</mu>
                <mu2>50</mu2>
              </ode>
              <torsional>
                <ode/>
              </torsional>
            </friction>
            <contact>
              <ode/>
            </contact>
            <bounce/>
          </surface>
          <max_contacts>10</max_contacts>
        </collision>
        <visual name='visual'>
          <cast_shadows>0</cast_shadows>
          <geometry>
            <plane>
              <normal>0 0 1</normal>
              <size>100 100</size>
            </plane>
          </geometry>
          <material>
            <script>
              <uri>file://media/materials/scripts/gazebo.material</uri>
              <name>Gazebo/Grey</name>
            </script>
          </material>
        </visual>
        <self_collide>0</self_collide>
        <enable_wind>0</enable_wind>
        <kinematic>0</kinematic>
      </link>
    </model>
    <light name='sun' type='directional'>
      <cast_shadows>1</cast_shadows>
      <pose>0 0 10 0 -0 0</pose>
      <diffuse>0.8 0.8 0.8 1</diffuse>
      <specular>0.2 0.2 0.2 1</specular>
      <attenuation>
        <range>1000</range>
        <constant>0.9</constant>
        <linear>0.01</linear>
        <quadratic>0.001</quadratic>
      </attenuation>
      <direction>-0.5 0.1 -0.9</direction>
      <spot>
        <inner_angle>0</inner_angle>
        <outer_angle>0</outer_angle>
        <falloff>0</falloff>
      </spot>
    </light>
    <model name='wall_1'>
      <static>1</static>
      <pose>3 0 0.5 0 -0 0</pose>
      <link name='link'>
        <collision name='collision'>
          <geometry>
            <box>
              <size>0.2 4 1</size>
            </box>
          </geometry>
          <max_contacts>10</max_contacts>
          <surface>
            <contact>
              <ode/>
            </contact>
            <bounce/>
            <friction>
              <torsional>
                <ode/>
              </torsional>
              <ode/>
            </friction>
          </surface>
        </collision>
        <visual name='visual'>
          <geometry>
            <box>
              <size>0.2 4 1</size>
            </box>
          </geometry>
          <material>
            <ambient>0.8 0.2 0.2 1</ambient>
          </material>
        </visual>
        <self_collide>0</self_collide>
        <enable_wind>0</enable_wind>
        <kinematic>0</kinematic>
      </link>
    </model>
    <model name='wall_2'>
      <static>1</static>
      <pose>-3 0 0.5 0 -0 0</pose>
      <link name='link'>
        <collision name='collision'>
          <geometry>
            <box>
              <size>0.2 4 1</size>
            </box>
          </geometry>
          <max_contacts>10</max_contacts>
          <surface>
            <contact>
              <ode/>
            </contact>
            <bounce/>
            <friction>
              <torsional>
                <ode/>
              </torsional>
              <ode/>
            </friction>
          </surface>
        </collision>
        <visual name='visual'>
          <geometry>
            <box>
              <size>0.2 4 1</size>
            </box>
          </geometry>
          <material>
            <ambient>0.2 0.2 0.8 1</ambient>
          </material>
        </visual>
        <self_collide>0</self_collide>
        <enable_wind>0</enable_wind>
        <kinematic>0</kinematic>
      </link>
    </model>
    <model name='box_1'>
      <static>1</static>
      <pose>2 1.5 0.25 0 -0 0</pose>
      <link name='link'>
        <collision name='collision'>
          <geometry>
            <box>
              <size>0.5 0.5 0.5</size>
            </box>
          </geometry>
          <max_contacts>10</max_contacts>
          <surface>
            <contact>
              <ode/>
            </contact>
            <bounce/>
            <friction>
              <torsional>
                <ode/>
              </torsional>
              <ode/>
            </friction>
          </surface>
        </collision>
        <visual name='visual'>
          <geometry>
            <box>
              <size>0.5 0.5 0.5</size>
            </box>
          </geometry>
          <material>
            <ambient>0.2 0.8 0.2 1</ambient>
          </material>
        </visual>
        <self_collide>0</self_collide>
        <enable_wind>0</enable_wind>
        <kinematic>0</kinematic>
      </link>
    </model>
    <model name='box_2'>
      <static>1</static>
      <pose>-2 -1.5 0.25 0 -0 0</pose>
      <link name='link'>
        <collision name='collision'>
          <geometry>
            <box>
              <size>0.5 0.5 0.5</size>
            </box>
          </geometry>
          <max_contacts>10</max_contacts>
          <surface>
            <contact>
              <ode/>
            </contact>
            <bounce/>
            <friction>
              <torsional>
                <ode/>
              </torsional>
              <ode/>
            </friction>
          </surface>
        </collision>
        <visual name='visual'>
          <geometry>
            <box>
              <size>0.5 0.5 0.5</size>
            </box>
          </geometry>
          <material>
            <ambient>0.8 0.8 0.2 1</ambient>
          </material>
        </visual>
        <self_collide>0</self_collide>
        <enable_wind>0</enable_wind>
        <kinematic>0</kinematic>
      </link>
    </model>
    <model name='cylinder_1'>
      <static>1</static>
      <pose>0 2.5 0.5 0 -0 0</pose>
      <link name='link'>
        <collision name='collision'>
          <geometry>
            <cylinder>
              <radius>0.3</radius>
              <length>1</length>
            </cylinder>
          </geometry>
          <max_contacts>10</max_contacts>
          <surface>
            <contact>
              <ode/>
            </contact>
            <bounce/>
            <friction>
              <torsional>
                <ode/>
              </torsional>
              <ode/>
            </friction>
          </surface>
        </collision>
        <visual name='visual'>
          <geometry>
            <cylinder>
              <radius>0.3</radius>
              <length>1</length>
            </cylinder>
          </geometry>
          <material>
            <ambient>0.8 0.4 0 1</ambient>
          </material>
        </visual>
        <self_collide>0</self_collide>
        <enable_wind>0</enable_wind>
        <kinematic>0</kinematic>
      </link>
    </model>
    <gravity>0 0 -9.8</gravity>
    <magnetic_field>6e-06 2.3e-05 -4.2e-05</magnetic_field>
    <atmosphere type='adiabatic'/>
    <physics type='ode'>
      <max_step_size>0.001</max_step_size>
      <real_time_factor>1</real_time_factor>
      <real_time_update_rate>1000</real_time_update_rate>
    </physics>
    <scene>
      <ambient>0.4 0.4 0.4 1</ambient>
      <background>0.7 0.7 0.7 1</background>
      <shadows>1</shadows>
    </scene>
    <audio>
      <device>default</device>
    </audio>
    <wind/>
    <spherical_coordinates>
      <surface_model>EARTH_WGS84</surface_model>
      <latitude_deg>0</latitude_deg>
      <longitude_deg>0</longitude_deg>
      <elevation>0</elevation>
      <heading_deg>0</heading_deg>
    </spherical_coordinates>
    <model name='go2'>
      <link name='base_link'>
        <inertial>
          <pose>0.040468 0 0.007755 0 -0 0</pose>
          <mass>7.762</mass>
          <inertia>
            <ixx>0.0364988</ixx>
            <ixy>0.00012166</ixy>
            <ixz>-0.0147616</ixz>
            <iyy>0.134069</iyy>
            <iyz>-3.12e-05</iyz>
            <izz>0.132178</izz>
          </inertia>
        </inertial>
        <collision name='base_link_fixed_joint_lump__trunk_collision'>
          <pose>0 0 0 0 -0 0</pose>
          <geometry>
            <box>
              <size>0.3762 0.0935 0.114</size>
            </box>
          </geometry>
          <surface>
            <contact>
              <ode>
                <kp>10000</kp>
                <kd>1</kd>
              </ode>
            </contact>
            <friction>
              <ode>
                <mu>0.2</mu>
                <mu2>0.2</mu2>
              </ode>
              <torsional>
                <ode/>
              </torsional>
            </friction>
            <bounce/>
          </surface>
          <max_contacts>10</max_contacts>
        </collision>
        <collision name='base_link_fixed_joint_lump__imu_link_collision_1'>
          <pose>0 0 0 0 -0 0</pose>
          <geometry>
            <box>
              <size>0.001 0.001 0.001</size>
            </box>
          </geometry>
          <surface>
            <contact>
              <ode/>
            </contact>
            <friction>
              <ode/>
              <torsional>
                <ode/>
              </torsional>
            </friction>
            <bounce/>
          </surface>
          <max_contacts>10</max_contacts>
        </collision>
        <collision name='base_link_fixed_joint_lump__velodyne_base_link_collision_2'>
          <pose>0.2 0 0.11585 0 -0 0</pose>
          <geometry>
            <cylinder>
              <length>0.0717</length>
              <radius>0.0516</radius>
            </cylinder>
          </geometry>
          <max_contacts>10</max_contacts>
          <surface>
            <contact>
              <ode/>
            </contact>
            <bounce/>
            <friction>
              <torsional>
                <ode/>
              </torsional>
              <ode/>
            </friction>
          </surface>
        </collision>
        <visual name='base_link_visual'>
          <pose>0 0 0 0 -0 0</pose>
          <geometry>
            <box>
              <size>0.001 0.001 0.001</size>
            </box>
          </geometry>
        </visual>
        <visual name='base_link_fixed_joint_lump__trunk_visual_1'>
          <pose>0 0 0 0 -0 0</pose>
          <geometry>
            <mesh>
              <scale>1 1 1</scale>
              <uri>file:///home/allkg/go2_sim_ws/install/go2_description/share/go2_description/meshes/trunk.dae</uri>
            </mesh>
          </geometry>
        </visual>
        <visual name='base_link_fixed_joint_lump__imu_link_visual_2'>
          <pose>0 0 0 0 -0 0</pose>
          <geometry>
            <box>
              <size>0.001 0.001 0.001</size>
            </box>
          </geometry>
        </visual>
        <visual name='base_link_fixed_joint_lump__velodyne_base_link_visual_3'>
          <pose>0.2 0 0.08 0 -0 0</pose>
          <geometry>
            <mesh>
              <scale>1 1 1</scale>
              <uri>file:///opt/ros/humble/share/velodyne_description/meshes/VLP16_base_1.dae</uri>
            </mesh>
          </geometry>
        </visual>
        <visual name='base_link_fixed_joint_lump__velodyne_base_link_visual_4'>
          <pose>0.2 0 0.08 0 -0 0</pose>
          <geometry>
            <mesh>
              <scale>1 1 1</scale>
              <uri>file:///opt/ros/humble/share/velodyne_description/meshes/VLP16_base_2.dae</uri>
            </mesh>
          </geometry>
        </visual>
        <visual name='base_link_fixed_joint_lump__velodyne_visual_5'>
          <pose>0.2 0 0.08 0 -0 0</pose>
          <geometry>
            <mesh>
              <scale>1 1 1</scale>
              <uri>file:///opt/ros/humble/share/velodyne_description/meshes/VLP16_scan.dae</uri>
            </mesh>
          </geometry>
        </visual>
        <sensor name='imu_sensor' type='imu'>
          <always_on>1</always_on>
          <update_rate>100</update_rate>
          <imu>
            <angular_velocity>
              <x>
                <noise type='gaussian'>
                  <mean>0</mean>
                  <stddev>0.0002</stddev>
                </noise>
              </x>
              <y>
                <noise type='gaussian'>
                  <mean>0</mean>
                  <stddev>0.0002</stddev>
                </noise>
              </y>
              <z>
                <noise type='gaussian'>
                  <mean>0</mean>
                  <stddev>0.0002</stddev>
                </noise>
              </z>
            </angular_velocity>
            <linear_acceleration>
              <x>
                <noise type='gaussian'>
                  <mean>0</mean>
                  <stddev>0.017</stddev>
                </noise>
              </x>
              <y>
                <noise type='gaussian'>
                  <mean>0</mean>
                  <stddev>0.017</stddev>
                </noise>
              </y>
              <z>
                <noise type='gaussian'>
                  <mean>0</mean>
                  <stddev>0.017</stddev>
                </noise>
              </z>
            </linear_acceleration>
          </imu>
          <plugin name='imu_plugin' filename='libgazebo_ros_imu_sensor.so'>
            <ros>
              <namespace>imu</namespace>
              <remapping>~/out:=data</remapping>
            </ros>
            <initial_orientation_as_reference>0</initial_orientation_as_reference>
          </plugin>
          <pose>0 0 0 0 -0 0</pose>
        </sensor>
        <sensor name='velodyne-VLP16' type='ray'>
          <visualize>0</visualize>
          <update_rate>10</update_rate>
          <ray>
            <scan>
              <horizontal>
                <samples>440</samples>
                <resolution>1</resolution>
                <min_angle>-3.14159</min_angle>
                <max_angle>3.14159</max_angle>
              </horizontal>
              <vertical>
                <samples>16</samples>
                <resolution>1</resolution>
                <min_angle>-0.261799</min_angle>
                <max_angle>0.261799</max_angle>
              </vertical>
            </scan>
            <range>
              <min>0.3</min>
              <max>131</max>
              <resolution>0.001</resolution>
            </range>
            <noise>
              <type>gaussian</type>
              <mean>0</mean>
              <stddev>0</stddev>
            </noise>
          </ray>
          <plugin name='gazebo_ros_laser_controller' filename='libgazebo_ros_velodyne_laser.so'>
            <ros>
              <namespace>/</namespace>
              <remapping>~/out:=velodyne_points</remapping>
            </ros>
            <frame_name>velodyne</frame_name>
            <organize_cloud>0</organize_cloud>
            <min_range>0.9</min_range>
            <max_range>130.0</max_range>
            <gaussian_noise>0.008</gaussian_noise>
          </plugin>
          <pose>0.2 0 0.1177 0 -0 0</pose>
        </sensor>
        <self_collide>0</self_collide>
        <enable_wind>0</enable_wind>
        <kinematic>0</kinematic>
      </link>
      <joint name='lf_hip_joint' type='revolute'>
        <pose relative_to='base_link'>0.1934 0.0465 0 0 -0 0</pose>
        <parent>base_link</parent>
        <child>lf_hip_link</child>
        <axis>
          <xyz>1 0 0</xyz>
          <limit>
            <lower>-1.0472</lower>
            <upper>1.0472</upper>
            <effort>23.7</effort>
            <velocity>30.1</velocity>
          </limit>
          <dynamics>
            <damping>0.01</damping>
            <friction>0.2</friction>
            <spring_reference>0</spring_reference>
            <spring_stiffness>0</spring_stiffness>
          </dynamics>
        </axis>
      </joint>
      <link name='lf_hip_link'>
        <pose relative_to='lf_hip_joint'>0 0 0 0 -0 0</pose>
        <inertial>
          <pose>-0.0054 0.00194 -0.000105 0 -0 0</pose>
          <mass>0.678</mass>
          <inertia>
            <ixx>0.00048</ixx>
            <ixy>-3.01e-06</ixy>
            <ixz>1.11e-06</ixz>
            <iyy>0.000884</iyy>
            <iyz>-1.42e-06</iyz>
            <izz>0.000596</izz>
          </inertia>
        </inertial>
        <collision name='lf_hip_link_collision'>
          <pose>0 0.0955 0 1.5708 -0 0</pose>
          <geometry>
            <cylinder>
              <length>0.04</length>
              <radius>0.046</radius>
            </cylinder>
          </geometry>
          <surface>
            <contact>
              <ode/>
            </contact>
            <friction>
              <ode>
                <mu>0.2</mu>
                <mu2>0.2</mu2>
              </ode>
              <torsional>
                <ode/>
              </torsional>
            </friction>
            <bounce/>
          </surface>
          <max_contacts>10</max_contacts>
        </collision>
        <visual name='lf_hip_link_visual'>
          <pose>0 0 0 0 -0 0</pose>
          <geometry>
            <mesh>
              <scale>1 1 1</scale>
              <uri>file:///home/allkg/go2_sim_ws/install/go2_description/share/go2_description/meshes/hip.dae</uri>
            </mesh>
          </geometry>
        </visual>
        <self_collide>0</self_collide>
        <enable_wind>0</enable_wind>
        <kinematic>0</kinematic>
      </link>
      <joint name='lf_upper_leg_joint' type='revolute'>
        <pose relative_to='lf_hip_link'>0 0.0955 0 0 -0 0</pose>
        <parent>lf_hip_link</parent>
        <child>lf_upper_leg_link</child>
        <axis>
          <xyz>0 1 0</xyz>
          <limit>
            <lower>-1.5708</lower>
            <upper>3.4907</upper>
            <effort>23.7</effort>
            <velocity>30.1</velocity>
          </limit>
          <dynamics>
            <damping>0.01</damping>
            <friction>0.2</friction>
            <spring_reference>0</spring_reference>
            <spring_stiffness>0</spring_stiffness>
          </dynamics>
        </axis>
      </joint>
      <link name='lf_upper_leg_link'>
        <pose relative_to='lf_upper_leg_joint'>0 0 0 0 -0 0</pose>
        <inertial>
          <pose>-0.00374 -0.0223 -0.0327 0 -0 0</pose>
          <mass>1.152</mass>
          <inertia>
            <ixx>0.00584</ixx>
            <ixy>8.72e-05</ixy>
            <ixz>-0.000289</ixz>
            <iyy>0.0058</iyy>
            <iyz>0.000808</iyz>
            <izz>0.00103</izz>
          </inertia>
        </inertial>
        <collision name='lf_upper_leg_link_collision'>
          <pose>0 0 -0.1065 3.14159 1.57079 3.14159</pose>
          <geometry>
            <box>
              <size>0.213 0.0245 0.034</size>
            </box>
          </geometry>
          <surface>
            <contact>
              <ode>
                <kp>10000</kp>
                <kd>1</kd>
              </ode>
            </contact>
            <friction>
              <ode>
                <mu>0.2</mu>
                <mu2>0.2</mu2>
              </ode>
              <torsional>
                <ode/>
              </torsional>
            </friction>
            <bounce/>
          </surface>
          <max_contacts>10</max_contacts>
        </collision>
        <visual name='lf_upper_leg_link_visual'>
          <pose>0 0 0 0 -0 0</pose>
          <geometry>
            <mesh>
              <scale>1 1 1</scale>
              <uri>file:///home/allkg/go2_sim_ws/install/go2_description/share/go2_description/meshes/thigh.dae</uri>
            </mesh>
          </geometry>
        </visual>
        <self_collide>1</self_collide>
        <enable_wind>0</enable_wind>
        <kinematic>0</kinematic>
      </link>
      <joint name='lf_lower_leg_joint' type='revolute'>
        <pose relative_to='lf_upper_leg_link'>0 0 -0.213 0 -0 0</pose>
        <parent>lf_upper_leg_link</parent>
        <child>lf_lower_leg_link</child>
        <axis>
          <xyz>0 1 0</xyz>
          <limit>
            <lower>-2.7227</lower>
            <upper>-0.83776</upper>
            <effort>35.55</effort>
            <velocity>20.06</velocity>
          </limit>
          <dynamics>
            <damping>0.01</damping>
            <friction>0.2</friction>
            <spring_reference>0</spring_reference>
            <spring_stiffness>0</spring_stiffness>
          </dynamics>
        </axis>
      </joint>
      <link name='lf_lower_leg_link'>
        <pose relative_to='lf_lower_leg_joint'>0 0 0 0 -0 0</pose>
        <inertial>
          <pose>0.003944 -0.000702 -0.142477 0 -0 0</pose>
          <mass>0.214</mass>
          <inertia>
            <ixx>0.00150432</ixx>
            <ixy>5.70698e-07</ixy>
            <ixz>-5.98808e-06</ixz>
            <iyy>0.00152557</iyy>
            <iyz>1.24056e-05</iyz>
            <izz>4.38377e-05</izz>
          </inertia>
        </inertial>
        <collision name='lf_lower_leg_link_collision'>
          <pose>0 0 -0.1065 3.14159 1.57079 3.14159</pose>
          <geometry>
            <box>
              <size>0.213 0.016 0.016</size>
            </box>
          </geometry>
          <surface>
            <contact>
              <ode/>
            </contact>
            <friction>
              <ode>
                <mu>0.2</mu>
                <mu2>0.2</mu2>
              </ode>
              <torsional>
                <ode/>
              </torsional>
            </friction>
            <bounce/>
          </surface>
          <max_contacts>10</max_contacts>
        </collision>
        <collision name='lf_lower_leg_link_fixed_joint_lump__lf_foot_link_collision_1'>
          <pose>0 0 -0.213 0 -0 0</pose>
          <geometry>
            <sphere>
              <radius>0.02</radius>
            </sphere>
          </geometry>
          <surface>
            <contact>
              <ode>
                <kp>10000</kp>
                <kd>1</kd>
              </ode>
            </contact>
            <friction>
              <ode>
                <mu>0.6</mu>
                <mu2>0.6</mu2>
              </ode>
              <torsional>
                <ode/>
              </torsional>
            </friction>
            <bounce/>
          </surface>
          <max_contacts>10</max_contacts>
        </collision>
        <visual name='lf_lower_leg_link_visual'>
          <pose>0 0 0 0 -0 0</pose>
          <geometry>
            <mesh>
              <scale>1 1 1</scale>
              <uri>file:///home/allkg/go2_sim_ws/install/go2_description/share/go2_description/meshes/calf.dae</uri>
            </mesh>
          </geometry>
        </visual>
        <visual name='lf_lower_leg_link_fixed_joint_lump__lf_foot_link_visual_1'>
          <pose>0 0 -0.213 0 -0 0</pose>
          <geometry>
            <sphere>
              <radius>0.01</radius>
            </sphere>
          </geometry>
        </visual>
        <self_collide>1</self_collide>
        <self_collide>1</self_collide>
        <enable_wind>0</enable_wind>
        <kinematic>0</kinematic>
      </link>
      <joint name='lh_hip_joint' type='revolute'>
        <pose relative_to='base_link'>-0.1934 0.0465 0 0 -0 0</pose>
        <parent>base_link</parent>
        <child>lh_hip_link</child>
        <axis>
          <xyz>1 0 0</xyz>
          <limit>
            <lower>-1.0472</lower>
            <upper>1.0472</upper>
            <effort>23.7</effort>
            <velocity>30.1</velocity>
          </limit>
          <dynamics>
            <damping>0.01</damping>
            <friction>0.2</friction>
            <spring_reference>0</spring_reference>
            <spring_stiffness>0</spring_stiffness>
          </dynamics>
        </axis>
      </joint>
      <link name='lh_hip_link'>
        <pose relative_to='lh_hip_joint'>0 0 0 0 -0 0</pose>
        <inertial>
          <pose>0.0054 0.00194 -0.000105 0 -0 0</pose>
          <mass>0.678</mass>
          <inertia>
            <ixx>0.00048</ixx>
            <ixy>3.01e-06</ixy>
            <ixz>-1.11e-06</ixz>
            <iyy>0.000884</iyy>
            <iyz>-1.42e-06</iyz>
            <izz>0.000596</izz>
          </inertia>
        </inertial>
        <collision name='lh_hip_link_collision'>
          <pose>0 0.0955 0 1.5708 -0 0</pose>
          <geometry>
            <cylinder>
              <length>0.04</length>
              <radius>0.046</radius>
            </cylinder>
          </geometry>
          <max_contacts>10</max_contacts>
          <surface>
            <contact>
              <ode/>
            </contact>
            <bounce/>
            <friction>
              <torsional>
                <ode/>
              </torsional>
              <ode/>
            </friction>
          </surface>
        </collision>
        <visual name='lh_hip_link_visual'>
          <pose>0 0 0 3.14159 -0 3.14159</pose>
          <geometry>
            <mesh>
              <scale>1 1 1</scale>
              <uri>file:///home/allkg/go2_sim_ws/install/go2_description/share/go2_description/meshes/hip.dae</uri>
            </mesh>
          </geometry>
        </visual>
        <self_collide>0</self_collide>
        <enable_wind>0</enable_wind>
        <kinematic>0</kinematic>
      </link>
      <joint name='lh_upper_leg_joint' type='revolute'>
        <pose relative_to='lh_hip_link'>0 0.0955 0 0 -0 0</pose>
        <parent>lh_hip_link</parent>
        <child>lh_upper_leg_link</child>
        <axis>
          <xyz>0 1 0</xyz>
          <limit>
            <lower>-1.5708</lower>
            <upper>3.4907</upper>
            <effort>23.7</effort>
            <velocity>30.1</velocity>
          </limit>
          <dynamics>
            <damping>0.01</damping>
            <friction>0.2</friction>
            <spring_reference>0</spring_reference>
            <spring_stiffness>0</spring_stiffness>
          </dynamics>
        </axis>
      </joint>
      <link name='lh_upper_leg_link'>
        <pose relative_to='lh_upper_leg_joint'>0 0 0 0 -0 0</pose>
        <inertial>
          <pose>-0.00374 -0.0223 -0.0327 0 -0 0</pose>
          <mass>1.152</mass>
          <inertia>
            <ixx>0.00584</ixx>
            <ixy>8.72e-05</ixy>
            <ixz>-0.000289</ixz>
            <iyy>0.0058</iyy>
            <iyz>0.000808</iyz>
            <izz>0.00103</izz>
          </inertia>
        </inertial>
        <collision name='lh_upper_leg_link_collision'>
          <pose>0 0 -0.1065 3.14159 1.57079 3.14159</pose>
          <geometry>
            <box>
              <size>0.213 0.0245 0.034</size>
            </box>
          </geometry>
          <surface>
            <contact>
              <ode>
                <kp>10000</kp>
                <kd>1</kd>
              </ode>
            </contact>
            <friction>
              <ode>
                <mu>0.2</mu>
                <mu2>0.2</mu2>
              </ode>
              <torsional>
                <ode/>
              </torsional>
            </friction>
            <bounce/>
          </surface>
          <max_contacts>10</max_contacts>
        </collision>
        <visual name='lh_upper_leg_link_visual'>
          <pose>0 0 0 0 -0 0</pose>
          <geometry>
            <mesh>
              <scale>1 1 1</scale>
              <uri>file:///home/allkg/go2_sim_ws/install/go2_description/share/go2_description/meshes/thigh.dae</uri>
            </mesh>
          </geometry>
        </visual>
        <self_collide>1</self_collide>
        <enable_wind>0</enable_wind>
        <kinematic>0</kinematic>
      </link>
      <joint name='lh_lower_leg_joint' type='revolute'>
        <pose relative_to='lh_upper_leg_link'>0 0 -0.213 0 -0 0</pose>
        <parent>lh_upper_leg_link</parent>
        <child>lh_lower_leg_link</child>
        <axis>
          <xyz>0 1 0</xyz>
          <limit>
            <lower>-2.7227</lower>
            <upper>-0.83776</upper>
            <effort>35.55</effort>
            <velocity>20.06</velocity>
          </limit>
          <dynamics>
            <damping>0.01</damping>
            <friction>0.2</friction>
            <spring_reference>0</spring_reference>
            <spring_stiffness>0</spring_stiffness>
          </dynamics>
        </axis>
      </joint>
      <link name='lh_lower_leg_link'>
        <pose relative_to='lh_lower_leg_joint'>0 0 0 0 -0 0</pose>
        <inertial>
          <pose>0.003944 -0.000702 -0.142477 0 -0 0</pose>
          <mass>0.214</mass>
          <inertia>
            <ixx>0.00150432</ixx>
            <ixy>5.70698e-07</ixy>
            <ixz>-5.98808e-06</ixz>
            <iyy>0.00152557</iyy>
            <iyz>1.24056e-05</iyz>
            <izz>4.38377e-05</izz>
          </inertia>
        </inertial>
        <collision name='lh_lower_leg_link_collision'>
          <pose>0 0 -0.1065 3.14159 1.57079 3.14159</pose>
          <geometry>
            <box>
              <size>0.213 0.016 0.016</size>
            </box>
          </geometry>
          <surface>
            <contact>
              <ode/>
            </contact>
            <friction>
              <ode>
                <mu>0.2</mu>
                <mu2>0.2</mu2>
              </ode>
              <torsional>
                <ode/>
              </torsional>
            </friction>
            <bounce/>
          </surface>
          <max_contacts>10</max_contacts>
        </collision>
        <collision name='lh_lower_leg_link_fixed_joint_lump__lh_foot_link_collision_1'>
          <pose>0 0 -0.213 0 -0 0</pose>
          <geometry>
            <sphere>
              <radius>0.02</radius>
            </sphere>
          </geometry>
          <surface>
            <contact>
              <ode>
                <kp>10000</kp>
                <kd>1</kd>
              </ode>
            </contact>
            <friction>
              <ode>
                <mu>0.6</mu>
                <mu2>0.6</mu2>
              </ode>
              <torsional>
                <ode/>
              </torsional>
            </friction>
            <bounce/>
          </surface>
          <max_contacts>10</max_contacts>
        </collision>
        <visual name='lh_lower_leg_link_visual'>
          <pose>0 0 0 0 -0 0</pose>
          <geometry>
            <mesh>
              <scale>1 1 1</scale>
              <uri>file:///home/allkg/go2_sim_ws/install/go2_description/share/go2_description/meshes/calf.dae</uri>
            </mesh>
          </geometry>
        </visual>
        <visual name='lh_lower_leg_link_fixed_joint_lump__lh_foot_link_visual_1'>
          <pose>0 0 -0.213 0 -0 0</pose>
          <geometry>
            <sphere>
              <radius>0.01</radius>
            </sphere>
          </geometry>
        </visual>
        <self_collide>1</self_collide>
        <self_collide>1</self_collide>
        <enable_wind>0</enable_wind>
        <kinematic>0</kinematic>
      </link>
      <joint name='rf_hip_joint' type='revolute'>
        <pose relative_to='base_link'>0.1934 -0.0465 0 0 -0 0</pose>
        <parent>base_link</parent>
        <child>rf_hip_link</child>
        <axis>
          <xyz>1 0 0</xyz>
          <limit>
            <lower>-1.0472</lower>
            <upper>1.0472</upper>
            <effort>23.7</effort>
            <velocity>30.1</velocity>
          </limit>
          <dynamics>
            <damping>0.01</damping>
            <friction>0.2</friction>
            <spring_reference>0</spring_reference>
            <spring_stiffness>0</spring_stiffness>
          </dynamics>
        </axis>
      </joint>
      <link name='rf_hip_link'>
        <pose relative_to='rf_hip_joint'>0 0 0 0 -0 0</pose>
        <inertial>
          <pose>-0.0054 -0.00194 -0.000105 0 -0 0</pose>
          <mass>0.678</mass>
          <inertia>
            <ixx>0.00048</ixx>
            <ixy>3.01e-06</ixy>
            <ixz>1.11e-06</ixz>
            <iyy>0.000884</iyy>
            <iyz>1.42e-06</iyz>
            <izz>0.000596</izz>
          </inertia>
        </inertial>
        <collision name='rf_hip_link_collision'>
          <pose>0 -0.0955 0 1.5708 -0 0</pose>
          <geometry>
            <cylinder>
              <length>0.04</length>
              <radius>0.046</radius>
            </cylinder>
          </geometry>
          <max_contacts>10</max_contacts>
          <surface>
            <contact>
              <ode/>
            </contact>
            <bounce/>
            <friction>
              <torsional>
                <ode/>
              </torsional>
              <ode/>
            </friction>
          </surface>
        </collision>
        <visual name='rf_hip_link_visual'>
          <pose>0 0 0 3.14159 -0 0</pose>
          <geometry>
            <mesh>
              <scale>1 1 1</scale>
              <uri>file:///home/allkg/go2_sim_ws/install/go2_description/share/go2_description/meshes/hip.dae</uri>
            </mesh>
          </geometry>
        </visual>
        <self_collide>0</self_collide>
        <enable_wind>0</enable_wind>
        <kinematic>0</kinematic>
      </link>
      <joint name='rf_upper_leg_joint' type='revolute'>
        <pose relative_to='rf_hip_link'>0 -0.0955 0 0 -0 0</pose>
        <parent>rf_hip_link</parent>
        <child>rf_upper_leg_link</child>
        <axis>
          <xyz>0 1 0</xyz>
          <limit>
            <lower>-1.5708</lower>
            <upper>3.4907</upper>
            <effort>23.7</effort>
            <velocity>30.1</velocity>
          </limit>
          <dynamics>
            <damping>0.01</damping>
            <friction>0.2</friction>
            <spring_reference>0</spring_reference>
            <spring_stiffness>0</spring_stiffness>
          </dynamics>
        </axis>
      </joint>
      <link name='rf_upper_leg_link'>
        <pose relative_to='rf_upper_leg_joint'>0 0 0 0 -0 0</pose>
        <inertial>
          <pose>-0.00374 0.0223 -0.0327 0 -0 0</pose>
          <mass>1.152</mass>
          <inertia>
            <ixx>0.00584</ixx>
            <ixy>-8.72e-05</ixy>
            <ixz>-0.000289</ixz>
            <iyy>0.0058</iyy>
            <iyz>-0.000808</iyz>
            <izz>0.00103</izz>
          </inertia>
        </inertial>
        <collision name='rf_upper_leg_link_collision'>
          <pose>0 0 -0.1065 3.14159 1.57079 3.14159</pose>
          <geometry>
            <box>
              <size>0.213 0.0245 0.034</size>
            </box>
          </geometry>
          <surface>
            <contact>
              <ode>
                <kp>10000</kp>
                <kd>1</kd>
              </ode>
            </contact>
            <friction>
              <ode>
                <mu>0.2</mu>
                <mu2>0.2</mu2>
              </ode>
              <torsional>
                <ode/>
              </torsional>
            </friction>
            <bounce/>
          </surface>
          <max_contacts>10</max_contacts>
        </collision>
        <visual name='rf_upper_leg_link_visual'>
          <pose>0 0 0 0 -0 0</pose>
          <geometry>
            <mesh>
              <scale>1 1 1</scale>
              <uri>file:///home/allkg/go2_sim_ws/install/go2_description/share/go2_description/meshes/thigh_mirror.dae</uri>
            </mesh>
          </geometry>
        </visual>
        <self_collide>1</self_collide>
        <enable_wind>0</enable_wind>
        <kinematic>0</kinematic>
      </link>
      <joint name='rf_lower_leg_joint' type='revolute'>
        <pose relative_to='rf_upper_leg_link'>0 0 -0.213 0 -0 0</pose>
        <parent>rf_upper_leg_link</parent>
        <child>rf_lower_leg_link</child>
        <axis>
          <xyz>0 1 0</xyz>
          <limit>
            <lower>-2.7227</lower>
            <upper>-0.83776</upper>
            <effort>35.55</effort>
            <velocity>20.06</velocity>
          </limit>
          <dynamics>
            <damping>0.01</damping>
            <friction>0.2</friction>
            <spring_reference>0</spring_reference>
            <spring_stiffness>0</spring_stiffness>
          </dynamics>
        </axis>
      </joint>
      <link name='rf_lower_leg_link'>
        <pose relative_to='rf_lower_leg_joint'>0 0 0 0 -0 0</pose>
        <inertial>
          <pose>0.003944 -0.000702 -0.142477 0 -0 0</pose>
          <mass>0.214</mass>
          <inertia>
            <ixx>0.00150432</ixx>
            <ixy>5.70698e-07</ixy>
            <ixz>-5.98808e-06</ixz>
            <iyy>0.00152557</iyy>
            <iyz>1.24056e-05</iyz>
            <izz>4.38377e-05</izz>
          </inertia>
        </inertial>
        <collision name='rf_lower_leg_link_collision'>
          <pose>0 0 -0.1065 3.14159 1.57079 3.14159</pose>
          <geometry>
            <box>
              <size>0.213 0.016 0.016</size>
            </box>
          </geometry>
          <surface>
            <contact>
              <ode/>
            </contact>
            <friction>
              <ode>
                <mu>0.2</mu>
                <mu2>0.2</mu2>
              </ode>
              <torsional>
                <ode/>
              </torsional>
            </friction>
            <bounce/>
          </surface>
          <max_contacts>10</max_contacts>
        </collision>
        <collision name='rf_lower_leg_link_fixed_joint_lump__rf_foot_link_collision_1'>
          <pose>0 0 -0.213 0 -0 0</pose>
          <geometry>
            <sphere>
              <radius>0.02</radius>
            </sphere>
          </geometry>
          <surface>
            <contact>
              <ode>
                <kp>10000</kp>
                <kd>1</kd>
              </ode>
            </contact>
            <friction>
              <ode>
                <mu>0.6</mu>
                <mu2>0.6</mu2>
              </ode>
              <torsional>
                <ode/>
              </torsional>
            </friction>
            <bounce/>
          </surface>
          <max_contacts>10</max_contacts>
        </collision>
        <visual name='rf_lower_leg_link_visual'>
          <pose>0 0 0 0 -0 0</pose>
          <geometry>
            <mesh>
              <scale>1 1 1</scale>
              <uri>file:///home/allkg/go2_sim_ws/install/go2_description/share/go2_description/meshes/calf.dae</uri>
            </mesh>
          </geometry>
        </visual>
        <visual name='rf_lower_leg_link_fixed_joint_lump__rf_foot_link_visual_1'>
          <pose>0 0 -0.213 0 -0 0</pose>
          <geometry>
            <sphere>
              <radius>0.01</radius>
            </sphere>
          </geometry>
        </visual>
        <self_collide>1</self_collide>
        <self_collide>1</self_collide>
        <enable_wind>0</enable_wind>
        <kinematic>0</kinematic>
      </link>
      <joint name='rh_hip_joint' type='revolute'>
        <pose relative_to='base_link'>-0.1934 -0.0465 0 0 -0 0</pose>
        <parent>base_link</parent>
        <child>rh_hip_link</child>
        <axis>
          <xyz>1 0 0</xyz>
          <limit>
            <lower>-1.0472</lower>
            <upper>1.0472</upper>
            <effort>23.7</effort>
            <velocity>30.1</velocity>
          </limit>
          <dynamics>
            <damping>0.01</damping>
            <friction>0.2</friction>
            <spring_reference>0</spring_reference>
            <spring_stiffness>0</spring_stiffness>
          </dynamics>
        </axis>
      </joint>
      <link name='rh_hip_link'>
        <pose relative_to='rh_hip_joint'>0 0 0 0 -0 0</pose>
        <inertial>
          <pose>0.0054 -0.00194 -0.000105 0 -0 0</pose>
          <mass>0.678</mass>
          <inertia>
            <ixx>0.00048</ixx>
            <ixy>-3.01e-06</ixy>
            <ixz>-1.11e-06</ixz>
            <iyy>0.000884</iyy>
            <iyz>1.42e-06</iyz>
            <izz>0.000596</izz>
          </inertia>
        </inertial>
        <collision name='rh_hip_link_collision'>
          <pose>0 -0.0955 0 1.5708 -0 0</pose>
          <geometry>
            <cylinder>
              <length>0.04</length>
              <radius>0.046</radius>
            </cylinder>
          </geometry>
          <max_contacts>10</max_contacts>
          <surface>
            <contact>
              <ode/>
            </contact>
            <bounce/>
            <friction>
              <torsional>
                <ode/>
              </torsional>
              <ode/>
            </friction>
          </surface>
        </collision>
        <visual name='rh_hip_link_visual'>
          <pose>0 0 0 0 -0 3.14159</pose>
          <geometry>
            <mesh>
              <scale>1 1 1</scale>
              <uri>file:///home/allkg/go2_sim_ws/install/go2_description/share/go2_description/meshes/hip.dae</uri>
            </mesh>
          </geometry>
        </visual>
        <self_collide>0</self_collide>
        <enable_wind>0</enable_wind>
        <kinematic>0</kinematic>
      </link>
      <joint name='rh_upper_leg_joint' type='revolute'>
        <pose relative_to='rh_hip_link'>0 -0.0955 0 0 -0 0</pose>
        <parent>rh_hip_link</parent>
        <child>rh_upper_leg_link</child>
        <axis>
          <xyz>0 1 0</xyz>
          <limit>
            <lower>-1.5708</lower>
            <upper>3.4907</upper>
            <effort>23.7</effort>
            <velocity>30.1</velocity>
          </limit>
          <dynamics>
            <damping>0.01</damping>
            <friction>0.2</friction>
            <spring_reference>0</spring_reference>
            <spring_stiffness>0</spring_stiffness>
          </dynamics>
        </axis>
      </joint>
      <link name='rh_upper_leg_link'>
        <pose relative_to='rh_upper_leg_joint'>0 0 0 0 -0 0</pose>
        <inertial>
          <pose>-0.00374 0.0223 -0.0327 0 -0 0</pose>
          <mass>1.152</mass>
          <inertia>
            <ixx>0.00584</ixx>
            <ixy>-8.72e-05</ixy>
            <ixz>-0.000289</ixz>
            <iyy>0.0058</iyy>
            <iyz>-0.000808</iyz>
            <izz>0.00103</izz>
          </inertia>
        </inertial>
        <collision name='rh_upper_leg_link_collision'>
          <pose>0 0 -0.1065 3.14159 1.57079 3.14159</pose>
          <geometry>
            <box>
              <size>0.213 0.0245 0.034</size>
            </box>
          </geometry>
          <surface>
            <contact>
              <ode>
                <kp>10000</kp>
                <kd>1</kd>
              </ode>
            </contact>
            <friction>
              <ode>
                <mu>0.2</mu>
                <mu2>0.2</mu2>
              </ode>
              <torsional>
                <ode/>
              </torsional>
            </friction>
            <bounce/>
          </surface>
          <max_contacts>10</max_contacts>
        </collision>
        <visual name='rh_upper_leg_link_visual'>
          <pose>0 0 0 0 -0 0</pose>
          <geometry>
            <mesh>
              <scale>1 1 1</scale>
              <uri>file:///home/allkg/go2_sim_ws/install/go2_description/share/go2_description/meshes/thigh_mirror.dae</uri>
            </mesh>
          </geometry>
        </visual>
        <self_collide>1</self_collide>
        <enable_wind>0</enable_wind>
        <kinematic>0</kinematic>
      </link>
      <joint name='rh_lower_leg_joint' type='revolute'>
        <pose relative_to='rh_upper_leg_link'>0 0 -0.213 0 -0 0</pose>
        <parent>rh_upper_leg_link</parent>
        <child>rh_lower_leg_link</child>
        <axis>
          <xyz>0 1 0</xyz>
          <limit>
            <lower>-2.7227</lower>
            <upper>-0.83776</upper>
            <effort>35.55</effort>
            <velocity>20.06</velocity>
          </limit>
          <dynamics>
            <damping>0.01</damping>
            <friction>0.2</friction>
            <spring_reference>0</spring_reference>
            <spring_stiffness>0</spring_stiffness>
          </dynamics>
        </axis>
      </joint>
      <link name='rh_lower_leg_link'>
        <pose relative_to='rh_lower_leg_joint'>0 0 0 0 -0 0</pose>
        <inertial>
          <pose>0.003944 -0.000702 -0.142477 0 -0 0</pose>
          <mass>0.214</mass>
          <inertia>
            <ixx>0.00150432</ixx>
            <ixy>5.70698e-07</ixy>
            <ixz>-5.98808e-06</ixz>
            <iyy>0.00152557</iyy>
            <iyz>1.24056e-05</iyz>
            <izz>4.38377e-05</izz>
          </inertia>
        </inertial>
        <collision name='rh_lower_leg_link_collision'>
          <pose>0 0 -0.1065 3.14159 1.57079 3.14159</pose>
          <geometry>
            <box>
              <size>0.213 0.016 0.016</size>
            </box>
          </geometry>
          <surface>
            <contact>
              <ode/>
            </contact>
            <friction>
              <ode>
                <mu>0.2</mu>
                <mu2>0.2</mu2>
              </ode>
              <torsional>
                <ode/>
              </torsional>
            </friction>
            <bounce/>
          </surface>
          <max_contacts>10</max_contacts>
        </collision>
        <collision name='rh_lower_leg_link_fixed_joint_lump__rh_foot_link_collision_1'>
          <pose>0 0 -0.213 0 -0 0</pose>
          <geometry>
            <sphere>
              <radius>0.02</radius>
            </sphere>
          </geometry>
          <surface>
            <contact>
              <ode>
                <kp>10000</kp>
                <kd>1</kd>
              </ode>
            </contact>
            <friction>
              <ode>
                <mu>0.6</mu>
                <mu2>0.6</mu2>
              </ode>
              <torsional>
                <ode/>
              </torsional>
            </friction>
            <bounce/>
          </surface>
          <max_contacts>10</max_contacts>
        </collision>
        <visual name='rh_lower_leg_link_visual'>
          <pose>0 0 0 0 -0 0</pose>
          <geometry>
            <mesh>
              <scale>1 1 1</scale>
              <uri>file:///home/allkg/go2_sim_ws/install/go2_description/share/go2_description/meshes/calf.dae</uri>
            </mesh>
          </geometry>
        </visual>
        <visual name='rh_lower_leg_link_fixed_joint_lump__rh_foot_link_visual_1'>
          <pose>0 0 -0.213 0 -0 0</pose>
          <geometry>
            <sphere>
              <radius>0.01</radius>
            </sphere>
          </geometry>
        </visual>
        <self_collide>1</self_collide>
        <self_collide>1</self_collide>
        <enable_wind>0</enable_wind>
        <kinematic>0</kinematic>
      </link>
      <plugin name='p3d_base_controller' filename='libgazebo_ros_p3d.so'>
        <ros>
          <remapping>odom:=odom/ground_truth</remapping>
        </ros>
        <body_name>base_link</body_name>
        <frame_name>world</frame_name>
        <update_rate>10.0</update_rate>
        <xyz_offset>0 0 0</xyz_offset>
        <rpy_offset>0 0 0</rpy_offset>
        <gaussian_noise>0.01</gaussian_noise>
      </plugin>
      <static>0</static>
      <plugin name='gazebo_ros2_control' filename='libgazebo_ros2_control.so'>
        <parameters>/home/allkg/go2_sim_ws/install/go2_description/share/go2_description/config/ros_control/ros_control.yaml</parameters>
      </plugin>
      <pose>0 0 0.275 0 -0 0</pose>
    </model>
    <model name='unit_sphere'>
      <pose>0.644691 -2.88706 0.5 0 -0 0</pose>
      <link name='link'>
        <inertial>
          <mass>1</mass>
          <inertia>
            <ixx>0.1</ixx>
            <ixy>0</ixy>
            <ixz>0</ixz>
            <iyy>0.1</iyy>
            <iyz>0</iyz>
            <izz>0.1</izz>
          </inertia>
          <pose>0 0 0 0 -0 0</pose>
        </inertial>
        <collision name='collision'>
          <geometry>
            <sphere>
              <radius>0.5</radius>
            </sphere>
          </geometry>
          <max_contacts>10</max_contacts>
          <surface>
            <contact>
              <ode/>
            </contact>
            <bounce/>
            <friction>
              <torsional>
                <ode/>
              </torsional>
              <ode/>
            </friction>
          </surface>
        </collision>
        <visual name='visual'>
          <geometry>
            <sphere>
              <radius>0.5</radius>
            </sphere>
          </geometry>
          <material>
            <script>
              <name>Gazebo/Grey</name>
              <uri>file://media/materials/scripts/gazebo.material</uri>
            </script>
          </material>
        </visual>
        <self_collide>0</self_collide>
        <enable_wind>0</enable_wind>
        <kinematic>0</kinematic>
      </link>
    </model>
    <state world_name='perception_world'>
      <sim_time>439 777000000</sim_time>
      <real_time>265 288520085</real_time>
      <wall_time>1773932755 672644023</wall_time>
      <iterations>264375</iterations>
      <model name='box_1'>
        <pose>2 1.5 0.25 0 -0 0</pose>
        <scale>1 1 1</scale>
        <link name='link'>
          <pose>2 1.5 0.25 0 -0 0</pose>
          <velocity>0 0 0 0 -0 0</velocity>
          <acceleration>0 0 0 0 -0 0</acceleration>
          <wrench>0 0 0 0 -0 0</wrench>
        </link>
      </model>
      <model name='box_2'>
        <pose>-2 -1.5 0.25 0 -0 0</pose>
        <scale>1 1 1</scale>
        <link name='link'>
          <pose>-2 -1.5 0.25 0 -0 0</pose>
          <velocity>0 0 0 0 -0 0</velocity>
          <acceleration>0 0 0 0 -0 0</acceleration>
          <wrench>0 0 0 0 -0 0</wrench>
        </link>
      </model>
      <model name='cylinder_1'>
        <pose>0 2.5 0.5 0 -0 0</pose>
        <scale>1 1 1</scale>
        <link name='link'>
          <pose>0 2.5 0.5 0 -0 0</pose>
          <velocity>0 0 0 0 -0 0</velocity>
          <acceleration>0 0 0 0 -0 0</acceleration>
          <wrench>0 0 0 0 -0 0</wrench>
        </link>
      </model>
      <model name='go2'>
        <pose>0.404096 0.010896 0.214639 8.1e-05 0.00247 -0.00983</pose>
        <scale>1 1 1</scale>
        <link name='base_link'>
          <pose>0.404096 0.010896 0.214639 8.1e-05 0.00247 -0.00983</pose>
          <velocity>0.005806 0.000305 0.007568 -0.063284 0.038814 0.014415</velocity>
          <acceleration>-2.08042 4.18921 -0.32286 -1.92318 -0.584984 1.53276</acceleration>
          <wrench>-16.1482 32.5167 -2.50604 0 -0 0</wrench>
        </link>
        <link name='lf_hip_link'>
          <pose>0.597943 0.055493 0.214164 0.033921 0.002474 -0.009678</pose>
          <velocity>0.005138 0.003006 -0.003144 -0.122068 0.040381 0.058635</velocity>
          <acceleration>-4.06333 7.97819 -10.1212 -0.470299 1.49394 -2.87349</acceleration>
          <wrench>-2.75494 5.40921 -6.86214 0 -0 0</wrench>
        </link>
        <link name='lf_lower_leg_link'>
          <pose>0.417727 0.156501 0.10551 0.077262 -1.09045 -0.078754</pose>
          <velocity>-0.003495 -0.019097 -0.006254 0.195764 -0.082765 -0.00945</velocity>
          <acceleration>119.431 7.08742 937.362 0.470624 0.35499 2.51864</acceleration>
          <wrench>25.5583 1.51671 200.595 0 -0 0</wrench>
        </link>
        <link name='lf_upper_leg_link'>
          <pose>0.598894 0.150932 0.21738 0.064509 1.01653 0.045134</pose>
          <velocity>0.005019 0.003103 -0.019103 -0.11979 0.072607 0.06192</velocity>
          <acceleration>-26.4622 5.15371 39.9612 0.925933 0.165608 0.357797</acceleration>
          <wrench>-30.4844 5.93708 46.0353 0 -0 0</wrench>
        </link>
        <link name='lh_hip_link'>
          <pose>0.211163 0.059295 0.21512 0.025054 0.002466 -0.009804</pose>
          <velocity>0.005125 -0.002414 0.012109 -0.012753 0.039094 -0.010093</velocity>
          <acceleration>-3.94394 -2.8153 10.1366 -0.648863 1.10629 -1.489</acceleration>
          <wrench>-2.674 -1.90877 6.87263 0 -0 0</wrench>
        </link>
        <link name='lh_lower_leg_link'>
          <pose>0.030962 0.159355 0.105553 0.056009 -1.09507 -0.059833</pose>
          <velocity>0.122334 0.000451 -0.180106 2.98157 -0.864076 -2.99438</velocity>
          <acceleration>-22.0987 2.87083 -188.067 -2.62614 1.46773 -0.124424</acceleration>
          <wrench>-4.72912 0.614358 -40.2463 0 -0 0</wrench>
        </link>
        <link name='lh_upper_leg_link'>
          <pose>0.212109 0.154761 0.217505 0.047634 1.01667 0.030659</pose>
          <velocity>0.003086 -0.002544 0.012865 -0.024572 -1.06203 -0.037529</velocity>
          <acceleration>-0.442963 -3.40828 -2.16814 2.13727 0.494054 -2.78</acceleration>
          <wrench>-0.510293 -3.92634 -2.4977 0 -0 0</wrench>
        </link>
        <link name='rf_hip_link'>
          <pose>0.597029 -0.037503 0.214157 -0.033787 0.002471 -0.009917</pose>
          <velocity>0.006481 0.003073 0.003548 0.002598 0.036579 0.042387</velocity>
          <acceleration>-1.01259 8.27334 -6.13876 2.08476 1.55408 0.295268</acceleration>
          <wrench>-0.686532 5.60933 -4.16208 0 -0 0</wrench>
        </link>
        <link name='rf_lower_leg_link'>
          <pose>0.414754 -0.134939 0.105667 -0.076007 -1.09376 0.058032</pose>
          <velocity>0.129846 -0.011899 -0.19028 -2.68186 -0.879299 2.91893</velocity>
          <acceleration>-19.5318 -18.6257 -190.125 2.63956 0.21987 -2.42648</acceleration>
          <wrench>-4.17981 -3.98591 -40.6868 0 -0 0</wrench>
        </link>
        <link name='rf_upper_leg_link'>
          <pose>0.596102 -0.132943 0.217372 -0.064343 1.01747 -0.064606</pose>
          <velocity>0.007187 0.002925 0.008386 -0.005956 -1.09394 0.08704</velocity>
          <acceleration>6.18791 5.47862 -7.47946 0.014237 1.3519 -2.48447</acceleration>
          <wrench>7.12847 6.31137 -8.61634 0 -0 0</wrench>
        </link>
        <link name='rh_hip_link'>
          <pose>0.210249 -0.033701 0.215113 -0.024269 0.002469 -0.009821</pose>
          <velocity>0.006498 -0.00236 0.0178 0.016262 0.037652 0.010691</velocity>
          <acceleration>-1.09766 -2.9066 13.3749 0.197502 -0.212933 -2.74668</acceleration>
          <wrench>-0.744216 -1.97068 9.06821 0 -0 0</wrench>
        </link>
        <link name='rh_lower_leg_link'>
          <pose>0.028162 -0.130118 0.105398 -0.054488 -1.09598 0.038839</pose>
          <velocity>0.124555 -0.009364 -0.171073 -2.89458 -0.921967 3.01653</velocity>
          <acceleration>-19.9207 -4.64366 -187.418 -2.63989 0.476861 -1.01245</acceleration>
          <wrench>-4.26303 -0.993743 -40.1074 0 -0 0</wrench>
        </link>
        <link name='rh_upper_leg_link'>
          <pose>0.209319 -0.129168 0.217426 -0.046107 1.01631 -0.04899</pose>
          <velocity>0.007172 -0.002351 0.018424 0.001439 -1.04489 0.046104</velocity>
          <acceleration>6.62632 -3.94133 0.081678 -1.76347 -1.22212 -2.81296</acceleration>
          <wrench>7.63352 -4.54042 0.094093 0 -0 0</wrench>
        </link>
      </model>
      <model name='ground_plane'>
        <pose>0 0 0 0 -0 0</pose>
        <scale>1 1 1</scale>
        <link name='link'>
          <pose>0 0 0 0 -0 0</pose>
          <velocity>0 0 0 0 -0 0</velocity>
          <acceleration>0 0 0 0 -0 0</acceleration>
          <wrench>0 0 0 0 -0 0</wrench>
        </link>
      </model>
      <model name='unit_sphere'>
        <pose>0.644691 -2.88706 1.1635 0 -0 0</pose>
        <scale>2.327 2.327 2.327</scale>
        <link name='link'>
          <pose>0.644691 -2.88706 1.1635 0 -0 0</pose>
          <velocity>0 0 0 0 -0 0</velocity>
          <acceleration>0 0 0 0 -0 0</acceleration>
          <wrench>0 0 0 0 -0 0</wrench>
        </link>
      </model>
      <model name='wall_1'>
        <pose>3 0 0.5 0 -0 0</pose>
        <scale>1 1 1</scale>
        <link name='link'>
          <pose>3 0 0.5 0 -0 0</pose>
          <velocity>0 0 0 0 -0 0</velocity>
          <acceleration>0 0 0 0 -0 0</acceleration>
          <wrench>0 0 0 0 -0 0</wrench>
        </link>
      </model>
      <model name='wall_2'>
        <pose>-3 0 0.5 0 -0 0</pose>
        <scale>2.85552 1.15129 1</scale>
        <link name='link'>
          <pose>-3 0 0.5 0 -0 0</pose>
          <velocity>0 0 0 0 -0 0</velocity>
          <acceleration>0 0 0 0 -0 0</acceleration>
          <wrench>0 0 0 0 -0 0</wrench>
        </link>
      </model>
      <light name='sun'>
        <pose>0 0 10 0 -0 0</pose>
      </light>
    </state>
    <gui fullscreen='0'>
      <camera name='user_camera'>
        <pose>1.89315 -3.33694 4.81817 -0 0.973225 2.16831</pose>
        <view_controller>orbit</view_controller>
        <projection_type>perspective</projection_type>
      </camera>
    </gui>
  </world>
</sdf>
